{"level":"ERROR","location":"[access_token_to_hsmtoken:287] data_ws","message":{"type":"cn","code":-300,"message":"Please provide valid token","s":"error"},"timestamp":"2024-10-21 16:03:50,835+0000","service":"FyersDataSocket"}
{"level":"ERROR","location":"[access_token_to_hsmtoken:272] data_ws","message":{"type":"cn","code":-99,"message":"Token is expired","s":"error"},"timestamp":"2024-10-23 08:57:50,898+0000","service":"FyersDataSocket"}
{"level":"ERROR","location":"[<lambda>:1663] data_ws","message":"Connection to remote host was lost.","timestamp":"2024-10-23 12:30:46,349+0000","service":"FyersDataSocket"}
{"level":"ERROR","location":"[<lambda>:1663] data_ws","message":"Connection to remote host was lost.","timestamp":"2024-10-23 14:14:44,557+0000","service":"FyersDataSocket"}
{"level":"ERROR","location":"[on_open:1519] data_ws","message":"Cannot resolve keyword 'symbol' into field. Choices are: id, ticker_market_cap, ticker_name, ticker_sector, ticker_sub_sector, ticker_symbol","timestamp":"2024-10-23 19:24:29,017+0000","service":"FyersDataSocket","exception":"Traceback (most recent call last):\n  File \"/home/akil/Desktop/Upwork/Trading Dhan - Krishnan/niftystudy/venv/lib/python3.12/site-packages/django/db/models/sql/query.py\", line 2195, in add_fields\n    join_info = self.setup_joins(\n                ^^^^^^^^^^^^^^^^^\n  File \"/home/akil/Desktop/Upwork/Trading Dhan - Krishnan/niftystudy/venv/lib/python3.12/site-packages/django/db/models/sql/query.py\", line 1863, in setup_joins\n    path, final_field, targets, rest = self.names_to_path(\n                                       ^^^^^^^^^^^^^^^^^^^\n  File \"/home/akil/Desktop/Upwork/Trading Dhan - Krishnan/niftystudy/venv/lib/python3.12/site-packages/django/db/models/sql/query.py\", line 1768, in names_to_path\n    raise FieldError(\ndjango.core.exceptions.FieldError: Cannot resolve keyword 'symbol' into field. Choices are: id, ticker_market_cap, ticker_name, ticker_sector, ticker_sub_sector, ticker_symbol\n\nDuring handling of the above exception, another exception occurred:\n\nTraceback (most recent call last):\n  File \"/home/akil/Desktop/Upwork/Trading Dhan - Krishnan/niftystudy/venv/lib/python3.12/site-packages/fyers_apiv3/FyersWebsocket/data_ws.py\", line 1517, in on_open\n    self.OnOpen()\n  File \"/home/akil/Desktop/Upwork/Trading Dhan - Krishnan/niftystudy/scannerpro/management/commands/start_fyers_socket.py\", line 22, in onopen\n    symbols = list(TickerBase.objects.values_list('symbol', flat=True))\n                   ^^^^^^^^^^^^^^^^^^^^^^^^^^^^^^^^^^^^^^^^^^^^^^^^^^^\n  File \"/home/akil/Desktop/Upwork/Trading Dhan - Krishnan/niftystudy/venv/lib/python3.12/site-packages/django/db/models/manager.py\", line 87, in manager_method\n    return getattr(self.get_queryset(), name)(*args, **kwargs)\n           ^^^^^^^^^^^^^^^^^^^^^^^^^^^^^^^^^^^^^^^^^^^^^^^^^^^\n  File \"/home/akil/Desktop/Upwork/Trading Dhan - Krishnan/niftystudy/venv/lib/python3.12/site-packages/django/db/models/query.py\", line 1392, in values_list\n    clone = self._values(*_fields, **expressions)\n            ^^^^^^^^^^^^^^^^^^^^^^^^^^^^^^^^^^^^^\n  File \"/home/akil/Desktop/Upwork/Trading Dhan - Krishnan/niftystudy/venv/lib/python3.12/site-packages/django/db/models/query.py\", line 1355, in _values\n    clone.query.set_values(fields)\n  File \"/home/akil/Desktop/Upwork/Trading Dhan - Krishnan/niftystudy/venv/lib/python3.12/site-packages/django/db/models/sql/query.py\", line 2500, in set_values\n    self.add_fields(field_names, True)\n  File \"/home/akil/Desktop/Upwork/Trading Dhan - Krishnan/niftystudy/venv/lib/python3.12/site-packages/django/db/models/sql/query.py\", line 2223, in add_fields\n    raise FieldError(\ndjango.core.exceptions.FieldError: Cannot resolve keyword 'symbol' into field. Choices are: id, ticker_market_cap, ticker_name, ticker_sector, ticker_sub_sector, ticker_symbol","exception_name":"FieldError"}
{"level":"ERROR","location":"[on_open:1520] data_ws","message":"Cannot resolve keyword 'symbol' into field. Choices are: id, ticker_market_cap, ticker_name, ticker_sector, ticker_sub_sector, ticker_symbol","timestamp":"2024-10-23 19:24:29,020+0000","service":"FyersDataSocket"}
{"level":"ERROR","location":"[__symbol_conversion:1352] data_ws","message":{"code":-300,"message":"Please provide a valid symbol","s":"error","type":"sub","invalid_symbols":["SBIN"]},"timestamp":"2024-10-23 19:24:56,788+0000","service":"FyersDataSocket"}
{"level":"ERROR","location":"[on_open:1519] data_ws","message":"name 'stocks' is not defined","timestamp":"2024-10-23 19:27:26,633+0000","service":"FyersDataSocket","exception":"Traceback (most recent call last):\n  File \"/home/akil/Desktop/Upwork/Trading Dhan - Krishnan/niftystudy/venv/lib/python3.12/site-packages/fyers_apiv3/FyersWebsocket/data_ws.py\", line 1517, in on_open\n    self.OnOpen()\n  File \"/home/akil/Desktop/Upwork/Trading Dhan - Krishnan/niftystudy/scannerpro/management/commands/start_fyers_socket.py\", line 23, in onopen\n    fyers_symbols = [\"NSE:\" + stock + \"-EQ\" for stock in stocks]\n                                                         ^^^^^^\nNameError: name 'stocks' is not defined","exception_name":"NameError"}
{"level":"ERROR","location":"[on_open:1520] data_ws","message":"name 'stocks' is not defined","timestamp":"2024-10-23 19:27:26,635+0000","service":"FyersDataSocket"}
{"level":"ERROR","location":"[access_token_to_hsmtoken:272] data_ws","message":{"type":"cn","code":-99,"message":"Token is expired","s":"error"},"timestamp":"2024-10-25 02:35:10,080+0000","service":"FyersDataSocket"}
{"level":"ERROR","location":"[<lambda>:1663] data_ws","message":"Connection to remote host was lost.","timestamp":"2024-10-25 02:42:15,744+0000","service":"FyersDataSocket"}
{"level":"ERROR","location":"[<lambda>:1663] data_ws","message":"[Errno -3] Temporary failure in name resolution","timestamp":"2024-10-25 04:46:15,618+0000","service":"FyersDataSocket"}
{"level":"ERROR","location":"[symbol_to_hsmtoken:126] data_ws","message":"HTTPSConnectionPool(host='api-t1.fyers.in', port=443): Max retries exceeded with url: /data/symbol-token (Caused by NameResolutionError(\"<urllib3.connection.HTTPSConnection object at 0x7bb421158c20>: Failed to resolve 'api-t1.fyers.in' ([Errno -3] Temporary failure in name resolution)\"))","timestamp":"2024-10-25 04:46:17,627+0000","service":"FyersDataSocket","exception":"Traceback (most recent call last):\n  File \"/home/akil/Desktop/Upwork/Trading Dhan - Krishnan/niftystudy/venv/lib/python3.12/site-packages/urllib3/connection.py\", line 199, in _new_conn\n    sock = connection.create_connection(\n           ^^^^^^^^^^^^^^^^^^^^^^^^^^^^^\n  File \"/home/akil/Desktop/Upwork/Trading Dhan - Krishnan/niftystudy/venv/lib/python3.12/site-packages/urllib3/util/connection.py\", line 60, in create_connection\n    for res in socket.getaddrinfo(host, port, family, socket.SOCK_STREAM):\n               ^^^^^^^^^^^^^^^^^^^^^^^^^^^^^^^^^^^^^^^^^^^^^^^^^^^^^^^^^^\n  File \"/usr/lib/python3.12/socket.py\", line 963, in getaddrinfo\n    for res in _socket.getaddrinfo(host, port, family, type, proto, flags):\n               ^^^^^^^^^^^^^^^^^^^^^^^^^^^^^^^^^^^^^^^^^^^^^^^^^^^^^^^^^^^\nsocket.gaierror: [Errno -3] Temporary failure in name resolution\n\nThe above exception was the direct cause of the following exception:\n\nTraceback (most recent call last):\n  File \"/home/akil/Desktop/Upwork/Trading Dhan - Krishnan/niftystudy/venv/lib/python3.12/site-packages/urllib3/connectionpool.py\", line 789, in urlopen\n    response = self._make_request(\n               ^^^^^^^^^^^^^^^^^^^\n  File \"/home/akil/Desktop/Upwork/Trading Dhan - Krishnan/niftystudy/venv/lib/python3.12/site-packages/urllib3/connectionpool.py\", line 490, in _make_request\n    raise new_e\n  File \"/home/akil/Desktop/Upwork/Trading Dhan - Krishnan/niftystudy/venv/lib/python3.12/site-packages/urllib3/connectionpool.py\", line 466, in _make_request\n    self._validate_conn(conn)\n  File \"/home/akil/Desktop/Upwork/Trading Dhan - Krishnan/niftystudy/venv/lib/python3.12/site-packages/urllib3/connectionpool.py\", line 1095, in _validate_conn\n    conn.connect()\n  File \"/home/akil/Desktop/Upwork/Trading Dhan - Krishnan/niftystudy/venv/lib/python3.12/site-packages/urllib3/connection.py\", line 693, in connect\n    self.sock = sock = self._new_conn()\n                       ^^^^^^^^^^^^^^^^\n  File \"/home/akil/Desktop/Upwork/Trading Dhan - Krishnan/niftystudy/venv/lib/python3.12/site-packages/urllib3/connection.py\", line 206, in _new_conn\n    raise NameResolutionError(self.host, self, e) from e\nurllib3.exceptions.NameResolutionError: <urllib3.connection.HTTPSConnection object at 0x7bb421158c20>: Failed to resolve 'api-t1.fyers.in' ([Errno -3] Temporary failure in name resolution)\n\nThe above exception was the direct cause of the following exception:\n\nTraceback (most recent call last):\n  File \"/home/akil/Desktop/Upwork/Trading Dhan - Krishnan/niftystudy/venv/lib/python3.12/site-packages/requests/adapters.py\", line 486, in send\n    resp = conn.urlopen(\n           ^^^^^^^^^^^^^\n  File \"/home/akil/Desktop/Upwork/Trading Dhan - Krishnan/niftystudy/venv/lib/python3.12/site-packages/urllib3/connectionpool.py\", line 843, in urlopen\n    retries = retries.increment(\n              ^^^^^^^^^^^^^^^^^^\n  File \"/home/akil/Desktop/Upwork/Trading Dhan - Krishnan/niftystudy/venv/lib/python3.12/site-packages/urllib3/util/retry.py\", line 519, in increment\n    raise MaxRetryError(_pool, url, reason) from reason  # type: ignore[arg-type]\n    ^^^^^^^^^^^^^^^^^^^^^^^^^^^^^^^^^^^^^^^^^^^^^^^^^^^\nurllib3.exceptions.MaxRetryError: HTTPSConnectionPool(host='api-t1.fyers.in', port=443): Max retries exceeded with url: /data/symbol-token (Caused by NameResolutionError(\"<urllib3.connection.HTTPSConnection object at 0x7bb421158c20>: Failed to resolve 'api-t1.fyers.in' ([Errno -3] Temporary failure in name resolution)\"))\n\nDuring handling of the above exception, another exception occurred:\n\nTraceback (most recent call last):\n  File \"/home/akil/Desktop/Upwork/Trading Dhan - Krishnan/niftystudy/venv/lib/python3.12/site-packages/fyers_apiv3/FyersWebsocket/data_ws.py\", line 63, in symbol_to_hsmtoken\n    response = requests.post(\n               ^^^^^^^^^^^^^^\n  File \"/home/akil/Desktop/Upwork/Trading Dhan - Krishnan/niftystudy/venv/lib/python3.12/site-packages/requests/api.py\", line 115, in post\n    return request(\"post\", url, data=data, json=json, **kwargs)\n           ^^^^^^^^^^^^^^^^^^^^^^^^^^^^^^^^^^^^^^^^^^^^^^^^^^^^\n  File \"/home/akil/Desktop/Upwork/Trading Dhan - Krishnan/niftystudy/venv/lib/python3.12/site-packages/requests/api.py\", line 59, in request\n    return session.request(method=method, url=url, **kwargs)\n           ^^^^^^^^^^^^^^^^^^^^^^^^^^^^^^^^^^^^^^^^^^^^^^^^^\n  File \"/home/akil/Desktop/Upwork/Trading Dhan - Krishnan/niftystudy/venv/lib/python3.12/site-packages/requests/sessions.py\", line 589, in request\n    resp = self.send(prep, **send_kwargs)\n           ^^^^^^^^^^^^^^^^^^^^^^^^^^^^^^\n  File \"/home/akil/Desktop/Upwork/Trading Dhan - Krishnan/niftystudy/venv/lib/python3.12/site-packages/requests/sessions.py\", line 703, in send\n    r = adapter.send(request, **kwargs)\n        ^^^^^^^^^^^^^^^^^^^^^^^^^^^^^^^\n  File \"/home/akil/Desktop/Upwork/Trading Dhan - Krishnan/niftystudy/venv/lib/python3.12/site-packages/requests/adapters.py\", line 519, in send\n    raise ConnectionError(e, request=request)\nrequests.exceptions.ConnectionError: HTTPSConnectionPool(host='api-t1.fyers.in', port=443): Max retries exceeded with url: /data/symbol-token (Caused by NameResolutionError(\"<urllib3.connection.HTTPSConnection object at 0x7bb421158c20>: Failed to resolve 'api-t1.fyers.in' ([Errno -3] Temporary failure in name resolution)\"))","exception_name":"ConnectionError"}
{"level":"ERROR","location":"[__symbol_conversion:1374] data_ws","message":"'NoneType' object is not subscriptable","timestamp":"2024-10-25 04:46:17,632+0000","service":"FyersDataSocket","exception":"Traceback (most recent call last):\n  File \"/home/akil/Desktop/Upwork/Trading Dhan - Krishnan/niftystudy/venv/lib/python3.12/site-packages/fyers_apiv3/FyersWebsocket/data_ws.py\", line 1333, in __symbol_conversion\n    if symbol_value[3] != \"\":\n       ~~~~~~~~~~~~^^^\nTypeError: 'NoneType' object is not subscriptable","exception_name":"TypeError"}
{"level":"ERROR","location":"[<lambda>:1663] data_ws","message":"[Errno -3] Temporary failure in name resolution","timestamp":"2024-10-25 04:46:20,619+0000","service":"FyersDataSocket"}
{"level":"ERROR","location":"[symbol_to_hsmtoken:126] data_ws","message":"HTTPSConnectionPool(host='api-t1.fyers.in', port=443): Max retries exceeded with url: /data/symbol-token (Caused by NameResolutionError(\"<urllib3.connection.HTTPSConnection object at 0x7bb42115a780>: Failed to resolve 'api-t1.fyers.in' ([Errno -3] Temporary failure in name resolution)\"))","timestamp":"2024-10-25 04:46:22,626+0000","service":"FyersDataSocket","exception":"Traceback (most recent call last):\n  File \"/home/akil/Desktop/Upwork/Trading Dhan - Krishnan/niftystudy/venv/lib/python3.12/site-packages/websocket/_http.py\", line 155, in _get_addrinfo_list\n    addrinfo_list = socket.getaddrinfo(\n                    ^^^^^^^^^^^^^^^^^^^\n  File \"/usr/lib/python3.12/socket.py\", line 963, in getaddrinfo\n    for res in _socket.getaddrinfo(host, port, family, type, proto, flags):\n               ^^^^^^^^^^^^^^^^^^^^^^^^^^^^^^^^^^^^^^^^^^^^^^^^^^^^^^^^^^^\nsocket.gaierror: [Errno -3] Temporary failure in name resolution\n\nDuring handling of the above exception, another exception occurred:\n\nTraceback (most recent call last):\n  File \"/home/akil/Desktop/Upwork/Trading Dhan - Krishnan/niftystudy/venv/lib/python3.12/site-packages/websocket/_app.py\", line 412, in setSock\n    self.sock.connect(\n  File \"/home/akil/Desktop/Upwork/Trading Dhan - Krishnan/niftystudy/venv/lib/python3.12/site-packages/websocket/_core.py\", line 249, in connect\n    self.sock, addrs = connect(url, self.sock_opt, proxy_info(**options),\n                       ^^^^^^^^^^^^^^^^^^^^^^^^^^^^^^^^^^^^^^^^^^^^^^^^^^\n  File \"/home/akil/Desktop/Upwork/Trading Dhan - Krishnan/niftystudy/venv/lib/python3.12/site-packages/websocket/_http.py\", line 122, in connect\n    addrinfo_list, need_tunnel, auth = _get_addrinfo_list(\n                                       ^^^^^^^^^^^^^^^^^^^\n  File \"/home/akil/Desktop/Upwork/Trading Dhan - Krishnan/niftystudy/venv/lib/python3.12/site-packages/websocket/_http.py\", line 167, in _get_addrinfo_list\n    raise WebSocketAddressException(e)\nwebsocket._exceptions.WebSocketAddressException: [Errno -3] Temporary failure in name resolution\n\nDuring handling of the above exception, another exception occurred:\n\nTraceback (most recent call last):\n  File \"/home/akil/Desktop/Upwork/Trading Dhan - Krishnan/niftystudy/venv/lib/python3.12/site-packages/urllib3/connection.py\", line 199, in _new_conn\n    sock = connection.create_connection(\n           ^^^^^^^^^^^^^^^^^^^^^^^^^^^^^\n  File \"/home/akil/Desktop/Upwork/Trading Dhan - Krishnan/niftystudy/venv/lib/python3.12/site-packages/urllib3/util/connection.py\", line 60, in create_connection\n    for res in socket.getaddrinfo(host, port, family, socket.SOCK_STREAM):\n               ^^^^^^^^^^^^^^^^^^^^^^^^^^^^^^^^^^^^^^^^^^^^^^^^^^^^^^^^^^\n  File \"/usr/lib/python3.12/socket.py\", line 963, in getaddrinfo\n    for res in _socket.getaddrinfo(host, port, family, type, proto, flags):\n               ^^^^^^^^^^^^^^^^^^^^^^^^^^^^^^^^^^^^^^^^^^^^^^^^^^^^^^^^^^^\nsocket.gaierror: [Errno -3] Temporary failure in name resolution\n\nThe above exception was the direct cause of the following exception:\n\nTraceback (most recent call last):\n  File \"/home/akil/Desktop/Upwork/Trading Dhan - Krishnan/niftystudy/venv/lib/python3.12/site-packages/urllib3/connectionpool.py\", line 789, in urlopen\n    response = self._make_request(\n               ^^^^^^^^^^^^^^^^^^^\n  File \"/home/akil/Desktop/Upwork/Trading Dhan - Krishnan/niftystudy/venv/lib/python3.12/site-packages/urllib3/connectionpool.py\", line 490, in _make_request\n    raise new_e\n  File \"/home/akil/Desktop/Upwork/Trading Dhan - Krishnan/niftystudy/venv/lib/python3.12/site-packages/urllib3/connectionpool.py\", line 466, in _make_request\n    self._validate_conn(conn)\n  File \"/home/akil/Desktop/Upwork/Trading Dhan - Krishnan/niftystudy/venv/lib/python3.12/site-packages/urllib3/connectionpool.py\", line 1095, in _validate_conn\n    conn.connect()\n  File \"/home/akil/Desktop/Upwork/Trading Dhan - Krishnan/niftystudy/venv/lib/python3.12/site-packages/urllib3/connection.py\", line 693, in connect\n    self.sock = sock = self._new_conn()\n                       ^^^^^^^^^^^^^^^^\n  File \"/home/akil/Desktop/Upwork/Trading Dhan - Krishnan/niftystudy/venv/lib/python3.12/site-packages/urllib3/connection.py\", line 206, in _new_conn\n    raise NameResolutionError(self.host, self, e) from e\nurllib3.exceptions.NameResolutionError: <urllib3.connection.HTTPSConnection object at 0x7bb42115a780>: Failed to resolve 'api-t1.fyers.in' ([Errno -3] Temporary failure in name resolution)\n\nThe above exception was the direct cause of the following exception:\n\nTraceback (most recent call last):\n  File \"/home/akil/Desktop/Upwork/Trading Dhan - Krishnan/niftystudy/venv/lib/python3.12/site-packages/requests/adapters.py\", line 486, in send\n    resp = conn.urlopen(\n           ^^^^^^^^^^^^^\n  File \"/home/akil/Desktop/Upwork/Trading Dhan - Krishnan/niftystudy/venv/lib/python3.12/site-packages/urllib3/connectionpool.py\", line 843, in urlopen\n    retries = retries.increment(\n              ^^^^^^^^^^^^^^^^^^\n  File \"/home/akil/Desktop/Upwork/Trading Dhan - Krishnan/niftystudy/venv/lib/python3.12/site-packages/urllib3/util/retry.py\", line 519, in increment\n    raise MaxRetryError(_pool, url, reason) from reason  # type: ignore[arg-type]\n    ^^^^^^^^^^^^^^^^^^^^^^^^^^^^^^^^^^^^^^^^^^^^^^^^^^^\nurllib3.exceptions.MaxRetryError: HTTPSConnectionPool(host='api-t1.fyers.in', port=443): Max retries exceeded with url: /data/symbol-token (Caused by NameResolutionError(\"<urllib3.connection.HTTPSConnection object at 0x7bb42115a780>: Failed to resolve 'api-t1.fyers.in' ([Errno -3] Temporary failure in name resolution)\"))\n\nDuring handling of the above exception, another exception occurred:\n\nTraceback (most recent call last):\n  File \"/home/akil/Desktop/Upwork/Trading Dhan - Krishnan/niftystudy/venv/lib/python3.12/site-packages/fyers_apiv3/FyersWebsocket/data_ws.py\", line 63, in symbol_to_hsmtoken\n    response = requests.post(\n               ^^^^^^^^^^^^^^\n  File \"/home/akil/Desktop/Upwork/Trading Dhan - Krishnan/niftystudy/venv/lib/python3.12/site-packages/requests/api.py\", line 115, in post\n    return request(\"post\", url, data=data, json=json, **kwargs)\n           ^^^^^^^^^^^^^^^^^^^^^^^^^^^^^^^^^^^^^^^^^^^^^^^^^^^^\n  File \"/home/akil/Desktop/Upwork/Trading Dhan - Krishnan/niftystudy/venv/lib/python3.12/site-packages/requests/api.py\", line 59, in request\n    return session.request(method=method, url=url, **kwargs)\n           ^^^^^^^^^^^^^^^^^^^^^^^^^^^^^^^^^^^^^^^^^^^^^^^^^\n  File \"/home/akil/Desktop/Upwork/Trading Dhan - Krishnan/niftystudy/venv/lib/python3.12/site-packages/requests/sessions.py\", line 589, in request\n    resp = self.send(prep, **send_kwargs)\n           ^^^^^^^^^^^^^^^^^^^^^^^^^^^^^^\n  File \"/home/akil/Desktop/Upwork/Trading Dhan - Krishnan/niftystudy/venv/lib/python3.12/site-packages/requests/sessions.py\", line 703, in send\n    r = adapter.send(request, **kwargs)\n        ^^^^^^^^^^^^^^^^^^^^^^^^^^^^^^^\n  File \"/home/akil/Desktop/Upwork/Trading Dhan - Krishnan/niftystudy/venv/lib/python3.12/site-packages/requests/adapters.py\", line 519, in send\n    raise ConnectionError(e, request=request)\nrequests.exceptions.ConnectionError: HTTPSConnectionPool(host='api-t1.fyers.in', port=443): Max retries exceeded with url: /data/symbol-token (Caused by NameResolutionError(\"<urllib3.connection.HTTPSConnection object at 0x7bb42115a780>: Failed to resolve 'api-t1.fyers.in' ([Errno -3] Temporary failure in name resolution)\"))","exception_name":"ConnectionError"}
{"level":"ERROR","location":"[__symbol_conversion:1374] data_ws","message":"'NoneType' object is not subscriptable","timestamp":"2024-10-25 04:46:22,629+0000","service":"FyersDataSocket","exception":"Traceback (most recent call last):\n  File \"/home/akil/Desktop/Upwork/Trading Dhan - Krishnan/niftystudy/venv/lib/python3.12/site-packages/websocket/_http.py\", line 155, in _get_addrinfo_list\n    addrinfo_list = socket.getaddrinfo(\n                    ^^^^^^^^^^^^^^^^^^^\n  File \"/usr/lib/python3.12/socket.py\", line 963, in getaddrinfo\n    for res in _socket.getaddrinfo(host, port, family, type, proto, flags):\n               ^^^^^^^^^^^^^^^^^^^^^^^^^^^^^^^^^^^^^^^^^^^^^^^^^^^^^^^^^^^\nsocket.gaierror: [Errno -3] Temporary failure in name resolution\n\nDuring handling of the above exception, another exception occurred:\n\nTraceback (most recent call last):\n  File \"/home/akil/Desktop/Upwork/Trading Dhan - Krishnan/niftystudy/venv/lib/python3.12/site-packages/websocket/_app.py\", line 412, in setSock\n    self.sock.connect(\n  File \"/home/akil/Desktop/Upwork/Trading Dhan - Krishnan/niftystudy/venv/lib/python3.12/site-packages/websocket/_core.py\", line 249, in connect\n    self.sock, addrs = connect(url, self.sock_opt, proxy_info(**options),\n                       ^^^^^^^^^^^^^^^^^^^^^^^^^^^^^^^^^^^^^^^^^^^^^^^^^^\n  File \"/home/akil/Desktop/Upwork/Trading Dhan - Krishnan/niftystudy/venv/lib/python3.12/site-packages/websocket/_http.py\", line 122, in connect\n    addrinfo_list, need_tunnel, auth = _get_addrinfo_list(\n                                       ^^^^^^^^^^^^^^^^^^^\n  File \"/home/akil/Desktop/Upwork/Trading Dhan - Krishnan/niftystudy/venv/lib/python3.12/site-packages/websocket/_http.py\", line 167, in _get_addrinfo_list\n    raise WebSocketAddressException(e)\nwebsocket._exceptions.WebSocketAddressException: [Errno -3] Temporary failure in name resolution\n\nDuring handling of the above exception, another exception occurred:\n\nTraceback (most recent call last):\n  File \"/home/akil/Desktop/Upwork/Trading Dhan - Krishnan/niftystudy/venv/lib/python3.12/site-packages/fyers_apiv3/FyersWebsocket/data_ws.py\", line 1333, in __symbol_conversion\n    if symbol_value[3] != \"\":\n       ~~~~~~~~~~~~^^^\nTypeError: 'NoneType' object is not subscriptable","exception_name":"TypeError"}
{"level":"ERROR","location":"[<lambda>:1663] data_ws","message":"[Errno -3] Temporary failure in name resolution","timestamp":"2024-10-25 04:46:25,620+0000","service":"FyersDataSocket"}
{"level":"ERROR","location":"[symbol_to_hsmtoken:126] data_ws","message":"HTTPSConnectionPool(host='api-t1.fyers.in', port=443): Max retries exceeded with url: /data/symbol-token (Caused by NameResolutionError(\"<urllib3.connection.HTTPSConnection object at 0x7bb42115b350>: Failed to resolve 'api-t1.fyers.in' ([Errno -3] Temporary failure in name resolution)\"))","timestamp":"2024-10-25 04:46:27,629+0000","service":"FyersDataSocket","exception":"Traceback (most recent call last):\n  File \"/home/akil/Desktop/Upwork/Trading Dhan - Krishnan/niftystudy/venv/lib/python3.12/site-packages/websocket/_http.py\", line 155, in _get_addrinfo_list\n    addrinfo_list = socket.getaddrinfo(\n                    ^^^^^^^^^^^^^^^^^^^\n  File \"/usr/lib/python3.12/socket.py\", line 963, in getaddrinfo\n    for res in _socket.getaddrinfo(host, port, family, type, proto, flags):\n               ^^^^^^^^^^^^^^^^^^^^^^^^^^^^^^^^^^^^^^^^^^^^^^^^^^^^^^^^^^^\nsocket.gaierror: [Errno -3] Temporary failure in name resolution\n\nDuring handling of the above exception, another exception occurred:\n\nTraceback (most recent call last):\n  File \"/home/akil/Desktop/Upwork/Trading Dhan - Krishnan/niftystudy/venv/lib/python3.12/site-packages/websocket/_app.py\", line 412, in setSock\n    self.sock.connect(\n  File \"/home/akil/Desktop/Upwork/Trading Dhan - Krishnan/niftystudy/venv/lib/python3.12/site-packages/websocket/_core.py\", line 249, in connect\n    self.sock, addrs = connect(url, self.sock_opt, proxy_info(**options),\n                       ^^^^^^^^^^^^^^^^^^^^^^^^^^^^^^^^^^^^^^^^^^^^^^^^^^\n  File \"/home/akil/Desktop/Upwork/Trading Dhan - Krishnan/niftystudy/venv/lib/python3.12/site-packages/websocket/_http.py\", line 122, in connect\n    addrinfo_list, need_tunnel, auth = _get_addrinfo_list(\n                                       ^^^^^^^^^^^^^^^^^^^\n  File \"/home/akil/Desktop/Upwork/Trading Dhan - Krishnan/niftystudy/venv/lib/python3.12/site-packages/websocket/_http.py\", line 167, in _get_addrinfo_list\n    raise WebSocketAddressException(e)\nwebsocket._exceptions.WebSocketAddressException: [Errno -3] Temporary failure in name resolution\n\nDuring handling of the above exception, another exception occurred:\n\nTraceback (most recent call last):\n  File \"/home/akil/Desktop/Upwork/Trading Dhan - Krishnan/niftystudy/venv/lib/python3.12/site-packages/urllib3/connection.py\", line 199, in _new_conn\n    sock = connection.create_connection(\n           ^^^^^^^^^^^^^^^^^^^^^^^^^^^^^\n  File \"/home/akil/Desktop/Upwork/Trading Dhan - Krishnan/niftystudy/venv/lib/python3.12/site-packages/urllib3/util/connection.py\", line 60, in create_connection\n    for res in socket.getaddrinfo(host, port, family, socket.SOCK_STREAM):\n               ^^^^^^^^^^^^^^^^^^^^^^^^^^^^^^^^^^^^^^^^^^^^^^^^^^^^^^^^^^\n  File \"/usr/lib/python3.12/socket.py\", line 963, in getaddrinfo\n    for res in _socket.getaddrinfo(host, port, family, type, proto, flags):\n               ^^^^^^^^^^^^^^^^^^^^^^^^^^^^^^^^^^^^^^^^^^^^^^^^^^^^^^^^^^^\nsocket.gaierror: [Errno -3] Temporary failure in name resolution\n\nThe above exception was the direct cause of the following exception:\n\nTraceback (most recent call last):\n  File \"/home/akil/Desktop/Upwork/Trading Dhan - Krishnan/niftystudy/venv/lib/python3.12/site-packages/urllib3/connectionpool.py\", line 789, in urlopen\n    response = self._make_request(\n               ^^^^^^^^^^^^^^^^^^^\n  File \"/home/akil/Desktop/Upwork/Trading Dhan - Krishnan/niftystudy/venv/lib/python3.12/site-packages/urllib3/connectionpool.py\", line 490, in _make_request\n    raise new_e\n  File \"/home/akil/Desktop/Upwork/Trading Dhan - Krishnan/niftystudy/venv/lib/python3.12/site-packages/urllib3/connectionpool.py\", line 466, in _make_request\n    self._validate_conn(conn)\n  File \"/home/akil/Desktop/Upwork/Trading Dhan - Krishnan/niftystudy/venv/lib/python3.12/site-packages/urllib3/connectionpool.py\", line 1095, in _validate_conn\n    conn.connect()\n  File \"/home/akil/Desktop/Upwork/Trading Dhan - Krishnan/niftystudy/venv/lib/python3.12/site-packages/urllib3/connection.py\", line 693, in connect\n    self.sock = sock = self._new_conn()\n                       ^^^^^^^^^^^^^^^^\n  File \"/home/akil/Desktop/Upwork/Trading Dhan - Krishnan/niftystudy/venv/lib/python3.12/site-packages/urllib3/connection.py\", line 206, in _new_conn\n    raise NameResolutionError(self.host, self, e) from e\nurllib3.exceptions.NameResolutionError: <urllib3.connection.HTTPSConnection object at 0x7bb42115b350>: Failed to resolve 'api-t1.fyers.in' ([Errno -3] Temporary failure in name resolution)\n\nThe above exception was the direct cause of the following exception:\n\nTraceback (most recent call last):\n  File \"/home/akil/Desktop/Upwork/Trading Dhan - Krishnan/niftystudy/venv/lib/python3.12/site-packages/requests/adapters.py\", line 486, in send\n    resp = conn.urlopen(\n           ^^^^^^^^^^^^^\n  File \"/home/akil/Desktop/Upwork/Trading Dhan - Krishnan/niftystudy/venv/lib/python3.12/site-packages/urllib3/connectionpool.py\", line 843, in urlopen\n    retries = retries.increment(\n              ^^^^^^^^^^^^^^^^^^\n  File \"/home/akil/Desktop/Upwork/Trading Dhan - Krishnan/niftystudy/venv/lib/python3.12/site-packages/urllib3/util/retry.py\", line 519, in increment\n    raise MaxRetryError(_pool, url, reason) from reason  # type: ignore[arg-type]\n    ^^^^^^^^^^^^^^^^^^^^^^^^^^^^^^^^^^^^^^^^^^^^^^^^^^^\nurllib3.exceptions.MaxRetryError: HTTPSConnectionPool(host='api-t1.fyers.in', port=443): Max retries exceeded with url: /data/symbol-token (Caused by NameResolutionError(\"<urllib3.connection.HTTPSConnection object at 0x7bb42115b350>: Failed to resolve 'api-t1.fyers.in' ([Errno -3] Temporary failure in name resolution)\"))\n\nDuring handling of the above exception, another exception occurred:\n\nTraceback (most recent call last):\n  File \"/home/akil/Desktop/Upwork/Trading Dhan - Krishnan/niftystudy/venv/lib/python3.12/site-packages/fyers_apiv3/FyersWebsocket/data_ws.py\", line 63, in symbol_to_hsmtoken\n    response = requests.post(\n               ^^^^^^^^^^^^^^\n  File \"/home/akil/Desktop/Upwork/Trading Dhan - Krishnan/niftystudy/venv/lib/python3.12/site-packages/requests/api.py\", line 115, in post\n    return request(\"post\", url, data=data, json=json, **kwargs)\n           ^^^^^^^^^^^^^^^^^^^^^^^^^^^^^^^^^^^^^^^^^^^^^^^^^^^^\n  File \"/home/akil/Desktop/Upwork/Trading Dhan - Krishnan/niftystudy/venv/lib/python3.12/site-packages/requests/api.py\", line 59, in request\n    return session.request(method=method, url=url, **kwargs)\n           ^^^^^^^^^^^^^^^^^^^^^^^^^^^^^^^^^^^^^^^^^^^^^^^^^\n  File \"/home/akil/Desktop/Upwork/Trading Dhan - Krishnan/niftystudy/venv/lib/python3.12/site-packages/requests/sessions.py\", line 589, in request\n    resp = self.send(prep, **send_kwargs)\n           ^^^^^^^^^^^^^^^^^^^^^^^^^^^^^^\n  File \"/home/akil/Desktop/Upwork/Trading Dhan - Krishnan/niftystudy/venv/lib/python3.12/site-packages/requests/sessions.py\", line 703, in send\n    r = adapter.send(request, **kwargs)\n        ^^^^^^^^^^^^^^^^^^^^^^^^^^^^^^^\n  File \"/home/akil/Desktop/Upwork/Trading Dhan - Krishnan/niftystudy/venv/lib/python3.12/site-packages/requests/adapters.py\", line 519, in send\n    raise ConnectionError(e, request=request)\nrequests.exceptions.ConnectionError: HTTPSConnectionPool(host='api-t1.fyers.in', port=443): Max retries exceeded with url: /data/symbol-token (Caused by NameResolutionError(\"<urllib3.connection.HTTPSConnection object at 0x7bb42115b350>: Failed to resolve 'api-t1.fyers.in' ([Errno -3] Temporary failure in name resolution)\"))","exception_name":"ConnectionError"}
{"level":"ERROR","location":"[__symbol_conversion:1374] data_ws","message":"'NoneType' object is not subscriptable","timestamp":"2024-10-25 04:46:27,631+0000","service":"FyersDataSocket","exception":"Traceback (most recent call last):\n  File \"/home/akil/Desktop/Upwork/Trading Dhan - Krishnan/niftystudy/venv/lib/python3.12/site-packages/websocket/_http.py\", line 155, in _get_addrinfo_list\n    addrinfo_list = socket.getaddrinfo(\n                    ^^^^^^^^^^^^^^^^^^^\n  File \"/usr/lib/python3.12/socket.py\", line 963, in getaddrinfo\n    for res in _socket.getaddrinfo(host, port, family, type, proto, flags):\n               ^^^^^^^^^^^^^^^^^^^^^^^^^^^^^^^^^^^^^^^^^^^^^^^^^^^^^^^^^^^\nsocket.gaierror: [Errno -3] Temporary failure in name resolution\n\nDuring handling of the above exception, another exception occurred:\n\nTraceback (most recent call last):\n  File \"/home/akil/Desktop/Upwork/Trading Dhan - Krishnan/niftystudy/venv/lib/python3.12/site-packages/websocket/_app.py\", line 412, in setSock\n    self.sock.connect(\n  File \"/home/akil/Desktop/Upwork/Trading Dhan - Krishnan/niftystudy/venv/lib/python3.12/site-packages/websocket/_core.py\", line 249, in connect\n    self.sock, addrs = connect(url, self.sock_opt, proxy_info(**options),\n                       ^^^^^^^^^^^^^^^^^^^^^^^^^^^^^^^^^^^^^^^^^^^^^^^^^^\n  File \"/home/akil/Desktop/Upwork/Trading Dhan - Krishnan/niftystudy/venv/lib/python3.12/site-packages/websocket/_http.py\", line 122, in connect\n    addrinfo_list, need_tunnel, auth = _get_addrinfo_list(\n                                       ^^^^^^^^^^^^^^^^^^^\n  File \"/home/akil/Desktop/Upwork/Trading Dhan - Krishnan/niftystudy/venv/lib/python3.12/site-packages/websocket/_http.py\", line 167, in _get_addrinfo_list\n    raise WebSocketAddressException(e)\nwebsocket._exceptions.WebSocketAddressException: [Errno -3] Temporary failure in name resolution\n\nDuring handling of the above exception, another exception occurred:\n\nTraceback (most recent call last):\n  File \"/home/akil/Desktop/Upwork/Trading Dhan - Krishnan/niftystudy/venv/lib/python3.12/site-packages/fyers_apiv3/FyersWebsocket/data_ws.py\", line 1333, in __symbol_conversion\n    if symbol_value[3] != \"\":\n       ~~~~~~~~~~~~^^^\nTypeError: 'NoneType' object is not subscriptable","exception_name":"TypeError"}
{"level":"ERROR","location":"[<lambda>:1663] data_ws","message":"[Errno -3] Temporary failure in name resolution","timestamp":"2024-10-25 04:46:30,621+0000","service":"FyersDataSocket"}
{"level":"ERROR","location":"[symbol_to_hsmtoken:126] data_ws","message":"HTTPSConnectionPool(host='api-t1.fyers.in', port=443): Max retries exceeded with url: /data/symbol-token (Caused by NameResolutionError(\"<urllib3.connection.HTTPSConnection object at 0x7bb421030950>: Failed to resolve 'api-t1.fyers.in' ([Errno -3] Temporary failure in name resolution)\"))","timestamp":"2024-10-25 04:46:32,629+0000","service":"FyersDataSocket","exception":"Traceback (most recent call last):\n  File \"/home/akil/Desktop/Upwork/Trading Dhan - Krishnan/niftystudy/venv/lib/python3.12/site-packages/websocket/_http.py\", line 155, in _get_addrinfo_list\n    addrinfo_list = socket.getaddrinfo(\n                    ^^^^^^^^^^^^^^^^^^^\n  File \"/usr/lib/python3.12/socket.py\", line 963, in getaddrinfo\n    for res in _socket.getaddrinfo(host, port, family, type, proto, flags):\n               ^^^^^^^^^^^^^^^^^^^^^^^^^^^^^^^^^^^^^^^^^^^^^^^^^^^^^^^^^^^\nsocket.gaierror: [Errno -3] Temporary failure in name resolution\n\nDuring handling of the above exception, another exception occurred:\n\nTraceback (most recent call last):\n  File \"/home/akil/Desktop/Upwork/Trading Dhan - Krishnan/niftystudy/venv/lib/python3.12/site-packages/websocket/_app.py\", line 412, in setSock\n    self.sock.connect(\n  File \"/home/akil/Desktop/Upwork/Trading Dhan - Krishnan/niftystudy/venv/lib/python3.12/site-packages/websocket/_core.py\", line 249, in connect\n    self.sock, addrs = connect(url, self.sock_opt, proxy_info(**options),\n                       ^^^^^^^^^^^^^^^^^^^^^^^^^^^^^^^^^^^^^^^^^^^^^^^^^^\n  File \"/home/akil/Desktop/Upwork/Trading Dhan - Krishnan/niftystudy/venv/lib/python3.12/site-packages/websocket/_http.py\", line 122, in connect\n    addrinfo_list, need_tunnel, auth = _get_addrinfo_list(\n                                       ^^^^^^^^^^^^^^^^^^^\n  File \"/home/akil/Desktop/Upwork/Trading Dhan - Krishnan/niftystudy/venv/lib/python3.12/site-packages/websocket/_http.py\", line 167, in _get_addrinfo_list\n    raise WebSocketAddressException(e)\nwebsocket._exceptions.WebSocketAddressException: [Errno -3] Temporary failure in name resolution\n\nDuring handling of the above exception, another exception occurred:\n\nTraceback (most recent call last):\n  File \"/home/akil/Desktop/Upwork/Trading Dhan - Krishnan/niftystudy/venv/lib/python3.12/site-packages/urllib3/connection.py\", line 199, in _new_conn\n    sock = connection.create_connection(\n           ^^^^^^^^^^^^^^^^^^^^^^^^^^^^^\n  File \"/home/akil/Desktop/Upwork/Trading Dhan - Krishnan/niftystudy/venv/lib/python3.12/site-packages/urllib3/util/connection.py\", line 60, in create_connection\n    for res in socket.getaddrinfo(host, port, family, socket.SOCK_STREAM):\n               ^^^^^^^^^^^^^^^^^^^^^^^^^^^^^^^^^^^^^^^^^^^^^^^^^^^^^^^^^^\n  File \"/usr/lib/python3.12/socket.py\", line 963, in getaddrinfo\n    for res in _socket.getaddrinfo(host, port, family, type, proto, flags):\n               ^^^^^^^^^^^^^^^^^^^^^^^^^^^^^^^^^^^^^^^^^^^^^^^^^^^^^^^^^^^\nsocket.gaierror: [Errno -3] Temporary failure in name resolution\n\nThe above exception was the direct cause of the following exception:\n\nTraceback (most recent call last):\n  File \"/home/akil/Desktop/Upwork/Trading Dhan - Krishnan/niftystudy/venv/lib/python3.12/site-packages/urllib3/connectionpool.py\", line 789, in urlopen\n    response = self._make_request(\n               ^^^^^^^^^^^^^^^^^^^\n  File \"/home/akil/Desktop/Upwork/Trading Dhan - Krishnan/niftystudy/venv/lib/python3.12/site-packages/urllib3/connectionpool.py\", line 490, in _make_request\n    raise new_e\n  File \"/home/akil/Desktop/Upwork/Trading Dhan - Krishnan/niftystudy/venv/lib/python3.12/site-packages/urllib3/connectionpool.py\", line 466, in _make_request\n    self._validate_conn(conn)\n  File \"/home/akil/Desktop/Upwork/Trading Dhan - Krishnan/niftystudy/venv/lib/python3.12/site-packages/urllib3/connectionpool.py\", line 1095, in _validate_conn\n    conn.connect()\n  File \"/home/akil/Desktop/Upwork/Trading Dhan - Krishnan/niftystudy/venv/lib/python3.12/site-packages/urllib3/connection.py\", line 693, in connect\n    self.sock = sock = self._new_conn()\n                       ^^^^^^^^^^^^^^^^\n  File \"/home/akil/Desktop/Upwork/Trading Dhan - Krishnan/niftystudy/venv/lib/python3.12/site-packages/urllib3/connection.py\", line 206, in _new_conn\n    raise NameResolutionError(self.host, self, e) from e\nurllib3.exceptions.NameResolutionError: <urllib3.connection.HTTPSConnection object at 0x7bb421030950>: Failed to resolve 'api-t1.fyers.in' ([Errno -3] Temporary failure in name resolution)\n\nThe above exception was the direct cause of the following exception:\n\nTraceback (most recent call last):\n  File \"/home/akil/Desktop/Upwork/Trading Dhan - Krishnan/niftystudy/venv/lib/python3.12/site-packages/requests/adapters.py\", line 486, in send\n    resp = conn.urlopen(\n           ^^^^^^^^^^^^^\n  File \"/home/akil/Desktop/Upwork/Trading Dhan - Krishnan/niftystudy/venv/lib/python3.12/site-packages/urllib3/connectionpool.py\", line 843, in urlopen\n    retries = retries.increment(\n              ^^^^^^^^^^^^^^^^^^\n  File \"/home/akil/Desktop/Upwork/Trading Dhan - Krishnan/niftystudy/venv/lib/python3.12/site-packages/urllib3/util/retry.py\", line 519, in increment\n    raise MaxRetryError(_pool, url, reason) from reason  # type: ignore[arg-type]\n    ^^^^^^^^^^^^^^^^^^^^^^^^^^^^^^^^^^^^^^^^^^^^^^^^^^^\nurllib3.exceptions.MaxRetryError: HTTPSConnectionPool(host='api-t1.fyers.in', port=443): Max retries exceeded with url: /data/symbol-token (Caused by NameResolutionError(\"<urllib3.connection.HTTPSConnection object at 0x7bb421030950>: Failed to resolve 'api-t1.fyers.in' ([Errno -3] Temporary failure in name resolution)\"))\n\nDuring handling of the above exception, another exception occurred:\n\nTraceback (most recent call last):\n  File \"/home/akil/Desktop/Upwork/Trading Dhan - Krishnan/niftystudy/venv/lib/python3.12/site-packages/fyers_apiv3/FyersWebsocket/data_ws.py\", line 63, in symbol_to_hsmtoken\n    response = requests.post(\n               ^^^^^^^^^^^^^^\n  File \"/home/akil/Desktop/Upwork/Trading Dhan - Krishnan/niftystudy/venv/lib/python3.12/site-packages/requests/api.py\", line 115, in post\n    return request(\"post\", url, data=data, json=json, **kwargs)\n           ^^^^^^^^^^^^^^^^^^^^^^^^^^^^^^^^^^^^^^^^^^^^^^^^^^^^\n  File \"/home/akil/Desktop/Upwork/Trading Dhan - Krishnan/niftystudy/venv/lib/python3.12/site-packages/requests/api.py\", line 59, in request\n    return session.request(method=method, url=url, **kwargs)\n           ^^^^^^^^^^^^^^^^^^^^^^^^^^^^^^^^^^^^^^^^^^^^^^^^^\n  File \"/home/akil/Desktop/Upwork/Trading Dhan - Krishnan/niftystudy/venv/lib/python3.12/site-packages/requests/sessions.py\", line 589, in request\n    resp = self.send(prep, **send_kwargs)\n           ^^^^^^^^^^^^^^^^^^^^^^^^^^^^^^\n  File \"/home/akil/Desktop/Upwork/Trading Dhan - Krishnan/niftystudy/venv/lib/python3.12/site-packages/requests/sessions.py\", line 703, in send\n    r = adapter.send(request, **kwargs)\n        ^^^^^^^^^^^^^^^^^^^^^^^^^^^^^^^\n  File \"/home/akil/Desktop/Upwork/Trading Dhan - Krishnan/niftystudy/venv/lib/python3.12/site-packages/requests/adapters.py\", line 519, in send\n    raise ConnectionError(e, request=request)\nrequests.exceptions.ConnectionError: HTTPSConnectionPool(host='api-t1.fyers.in', port=443): Max retries exceeded with url: /data/symbol-token (Caused by NameResolutionError(\"<urllib3.connection.HTTPSConnection object at 0x7bb421030950>: Failed to resolve 'api-t1.fyers.in' ([Errno -3] Temporary failure in name resolution)\"))","exception_name":"ConnectionError"}
{"level":"ERROR","location":"[__symbol_conversion:1374] data_ws","message":"'NoneType' object is not subscriptable","timestamp":"2024-10-25 04:46:32,630+0000","service":"FyersDataSocket","exception":"Traceback (most recent call last):\n  File \"/home/akil/Desktop/Upwork/Trading Dhan - Krishnan/niftystudy/venv/lib/python3.12/site-packages/websocket/_http.py\", line 155, in _get_addrinfo_list\n    addrinfo_list = socket.getaddrinfo(\n                    ^^^^^^^^^^^^^^^^^^^\n  File \"/usr/lib/python3.12/socket.py\", line 963, in getaddrinfo\n    for res in _socket.getaddrinfo(host, port, family, type, proto, flags):\n               ^^^^^^^^^^^^^^^^^^^^^^^^^^^^^^^^^^^^^^^^^^^^^^^^^^^^^^^^^^^\nsocket.gaierror: [Errno -3] Temporary failure in name resolution\n\nDuring handling of the above exception, another exception occurred:\n\nTraceback (most recent call last):\n  File \"/home/akil/Desktop/Upwork/Trading Dhan - Krishnan/niftystudy/venv/lib/python3.12/site-packages/websocket/_app.py\", line 412, in setSock\n    self.sock.connect(\n  File \"/home/akil/Desktop/Upwork/Trading Dhan - Krishnan/niftystudy/venv/lib/python3.12/site-packages/websocket/_core.py\", line 249, in connect\n    self.sock, addrs = connect(url, self.sock_opt, proxy_info(**options),\n                       ^^^^^^^^^^^^^^^^^^^^^^^^^^^^^^^^^^^^^^^^^^^^^^^^^^\n  File \"/home/akil/Desktop/Upwork/Trading Dhan - Krishnan/niftystudy/venv/lib/python3.12/site-packages/websocket/_http.py\", line 122, in connect\n    addrinfo_list, need_tunnel, auth = _get_addrinfo_list(\n                                       ^^^^^^^^^^^^^^^^^^^\n  File \"/home/akil/Desktop/Upwork/Trading Dhan - Krishnan/niftystudy/venv/lib/python3.12/site-packages/websocket/_http.py\", line 167, in _get_addrinfo_list\n    raise WebSocketAddressException(e)\nwebsocket._exceptions.WebSocketAddressException: [Errno -3] Temporary failure in name resolution\n\nDuring handling of the above exception, another exception occurred:\n\nTraceback (most recent call last):\n  File \"/home/akil/Desktop/Upwork/Trading Dhan - Krishnan/niftystudy/venv/lib/python3.12/site-packages/fyers_apiv3/FyersWebsocket/data_ws.py\", line 1333, in __symbol_conversion\n    if symbol_value[3] != \"\":\n       ~~~~~~~~~~~~^^^\nTypeError: 'NoneType' object is not subscriptable","exception_name":"TypeError"}
{"level":"ERROR","location":"[<lambda>:1663] data_ws","message":"[Errno -3] Temporary failure in name resolution","timestamp":"2024-10-25 04:46:35,622+0000","service":"FyersDataSocket"}
{"level":"ERROR","location":"[<lambda>:1663] data_ws","message":"Connection to remote host was lost.","timestamp":"2024-10-25 06:15:54,898+0000","service":"FyersDataSocket"}
{"level":"ERROR","location":"[symbol_to_hsmtoken:126] data_ws","message":"('Connection aborted.', ConnectionResetError(104, 'Connection reset by peer'))","timestamp":"2024-10-25 06:16:14,772+0000","service":"FyersDataSocket","exception":"Traceback (most recent call last):\n  File \"/home/akil/Desktop/Upwork/Trading Dhan - Krishnan/niftystudy/venv/lib/python3.12/site-packages/websocket/_app.py\", line 428, in setSock\n    dispatcher.read(self.sock.sock, read, check)\n  File \"/home/akil/Desktop/Upwork/Trading Dhan - Krishnan/niftystudy/venv/lib/python3.12/site-packages/websocket/_app.py\", line 99, in read\n    if not read_callback():\n           ^^^^^^^^^^^^^^^\n  File \"/home/akil/Desktop/Upwork/Trading Dhan - Krishnan/niftystudy/venv/lib/python3.12/site-packages/websocket/_app.py\", line 442, in read\n    raise e\n  File \"/home/akil/Desktop/Upwork/Trading Dhan - Krishnan/niftystudy/venv/lib/python3.12/site-packages/websocket/_app.py\", line 437, in read\n    op_code, frame = self.sock.recv_data_frame(True)\n                     ^^^^^^^^^^^^^^^^^^^^^^^^^^^^^^^\n  File \"/home/akil/Desktop/Upwork/Trading Dhan - Krishnan/niftystudy/venv/lib/python3.12/site-packages/websocket/_core.py\", line 406, in recv_data_frame\n    frame = self.recv_frame()\n            ^^^^^^^^^^^^^^^^^\n  File \"/home/akil/Desktop/Upwork/Trading Dhan - Krishnan/niftystudy/venv/lib/python3.12/site-packages/websocket/_core.py\", line 445, in recv_frame\n    return self.frame_buffer.recv_frame()\n           ^^^^^^^^^^^^^^^^^^^^^^^^^^^^^^\n  File \"/home/akil/Desktop/Upwork/Trading Dhan - Krishnan/niftystudy/venv/lib/python3.12/site-packages/websocket/_abnf.py\", line 338, in recv_frame\n    self.recv_header()\n  File \"/home/akil/Desktop/Upwork/Trading Dhan - Krishnan/niftystudy/venv/lib/python3.12/site-packages/websocket/_abnf.py\", line 294, in recv_header\n    header = self.recv_strict(2)\n             ^^^^^^^^^^^^^^^^^^^\n  File \"/home/akil/Desktop/Upwork/Trading Dhan - Krishnan/niftystudy/venv/lib/python3.12/site-packages/websocket/_abnf.py\", line 373, in recv_strict\n    bytes_ = self.recv(min(16384, shortage))\n             ^^^^^^^^^^^^^^^^^^^^^^^^^^^^^^^\n  File \"/home/akil/Desktop/Upwork/Trading Dhan - Krishnan/niftystudy/venv/lib/python3.12/site-packages/websocket/_core.py\", line 529, in _recv\n    return recv(self.sock, bufsize)\n           ^^^^^^^^^^^^^^^^^^^^^^^^\n  File \"/home/akil/Desktop/Upwork/Trading Dhan - Krishnan/niftystudy/venv/lib/python3.12/site-packages/websocket/_socket.py\", line 122, in recv\n    raise WebSocketConnectionClosedException(\nwebsocket._exceptions.WebSocketConnectionClosedException: Connection to remote host was lost.\n\nDuring handling of the above exception, another exception occurred:\n\nTraceback (most recent call last):\n  File \"/home/akil/Desktop/Upwork/Trading Dhan - Krishnan/niftystudy/venv/lib/python3.12/site-packages/urllib3/connectionpool.py\", line 789, in urlopen\n    response = self._make_request(\n               ^^^^^^^^^^^^^^^^^^^\n  File \"/home/akil/Desktop/Upwork/Trading Dhan - Krishnan/niftystudy/venv/lib/python3.12/site-packages/urllib3/connectionpool.py\", line 490, in _make_request\n    raise new_e\n  File \"/home/akil/Desktop/Upwork/Trading Dhan - Krishnan/niftystudy/venv/lib/python3.12/site-packages/urllib3/connectionpool.py\", line 466, in _make_request\n    self._validate_conn(conn)\n  File \"/home/akil/Desktop/Upwork/Trading Dhan - Krishnan/niftystudy/venv/lib/python3.12/site-packages/urllib3/connectionpool.py\", line 1095, in _validate_conn\n    conn.connect()\n  File \"/home/akil/Desktop/Upwork/Trading Dhan - Krishnan/niftystudy/venv/lib/python3.12/site-packages/urllib3/connection.py\", line 730, in connect\n    sock_and_verified = _ssl_wrap_socket_and_match_hostname(\n                        ^^^^^^^^^^^^^^^^^^^^^^^^^^^^^^^^^^^^\n  File \"/home/akil/Desktop/Upwork/Trading Dhan - Krishnan/niftystudy/venv/lib/python3.12/site-packages/urllib3/connection.py\", line 909, in _ssl_wrap_socket_and_match_hostname\n    ssl_sock = ssl_wrap_socket(\n               ^^^^^^^^^^^^^^^^\n  File \"/home/akil/Desktop/Upwork/Trading Dhan - Krishnan/niftystudy/venv/lib/python3.12/site-packages/urllib3/util/ssl_.py\", line 469, in ssl_wrap_socket\n    ssl_sock = _ssl_wrap_socket_impl(sock, context, tls_in_tls, server_hostname)\n               ^^^^^^^^^^^^^^^^^^^^^^^^^^^^^^^^^^^^^^^^^^^^^^^^^^^^^^^^^^^^^^^^^\n  File \"/home/akil/Desktop/Upwork/Trading Dhan - Krishnan/niftystudy/venv/lib/python3.12/site-packages/urllib3/util/ssl_.py\", line 513, in _ssl_wrap_socket_impl\n    return ssl_context.wrap_socket(sock, server_hostname=server_hostname)\n           ^^^^^^^^^^^^^^^^^^^^^^^^^^^^^^^^^^^^^^^^^^^^^^^^^^^^^^^^^^^^^^\n  File \"/usr/lib/python3.12/ssl.py\", line 455, in wrap_socket\n    return self.sslsocket_class._create(\n           ^^^^^^^^^^^^^^^^^^^^^^^^^^^^^\n  File \"/usr/lib/python3.12/ssl.py\", line 1042, in _create\n    self.do_handshake()\n  File \"/usr/lib/python3.12/ssl.py\", line 1320, in do_handshake\n    self._sslobj.do_handshake()\nConnectionResetError: [Errno 104] Connection reset by peer\n\nDuring handling of the above exception, another exception occurred:\n\nTraceback (most recent call last):\n  File \"/home/akil/Desktop/Upwork/Trading Dhan - Krishnan/niftystudy/venv/lib/python3.12/site-packages/requests/adapters.py\", line 486, in send\n    resp = conn.urlopen(\n           ^^^^^^^^^^^^^\n  File \"/home/akil/Desktop/Upwork/Trading Dhan - Krishnan/niftystudy/venv/lib/python3.12/site-packages/urllib3/connectionpool.py\", line 843, in urlopen\n    retries = retries.increment(\n              ^^^^^^^^^^^^^^^^^^\n  File \"/home/akil/Desktop/Upwork/Trading Dhan - Krishnan/niftystudy/venv/lib/python3.12/site-packages/urllib3/util/retry.py\", line 474, in increment\n    raise reraise(type(error), error, _stacktrace)\n          ^^^^^^^^^^^^^^^^^^^^^^^^^^^^^^^^^^^^^^^^\n  File \"/home/akil/Desktop/Upwork/Trading Dhan - Krishnan/niftystudy/venv/lib/python3.12/site-packages/urllib3/util/util.py\", line 38, in reraise\n    raise value.with_traceback(tb)\n  File \"/home/akil/Desktop/Upwork/Trading Dhan - Krishnan/niftystudy/venv/lib/python3.12/site-packages/urllib3/connectionpool.py\", line 789, in urlopen\n    response = self._make_request(\n               ^^^^^^^^^^^^^^^^^^^\n  File \"/home/akil/Desktop/Upwork/Trading Dhan - Krishnan/niftystudy/venv/lib/python3.12/site-packages/urllib3/connectionpool.py\", line 490, in _make_request\n    raise new_e\n  File \"/home/akil/Desktop/Upwork/Trading Dhan - Krishnan/niftystudy/venv/lib/python3.12/site-packages/urllib3/connectionpool.py\", line 466, in _make_request\n    self._validate_conn(conn)\n  File \"/home/akil/Desktop/Upwork/Trading Dhan - Krishnan/niftystudy/venv/lib/python3.12/site-packages/urllib3/connectionpool.py\", line 1095, in _validate_conn\n    conn.connect()\n  File \"/home/akil/Desktop/Upwork/Trading Dhan - Krishnan/niftystudy/venv/lib/python3.12/site-packages/urllib3/connection.py\", line 730, in connect\n    sock_and_verified = _ssl_wrap_socket_and_match_hostname(\n                        ^^^^^^^^^^^^^^^^^^^^^^^^^^^^^^^^^^^^\n  File \"/home/akil/Desktop/Upwork/Trading Dhan - Krishnan/niftystudy/venv/lib/python3.12/site-packages/urllib3/connection.py\", line 909, in _ssl_wrap_socket_and_match_hostname\n    ssl_sock = ssl_wrap_socket(\n               ^^^^^^^^^^^^^^^^\n  File \"/home/akil/Desktop/Upwork/Trading Dhan - Krishnan/niftystudy/venv/lib/python3.12/site-packages/urllib3/util/ssl_.py\", line 469, in ssl_wrap_socket\n    ssl_sock = _ssl_wrap_socket_impl(sock, context, tls_in_tls, server_hostname)\n               ^^^^^^^^^^^^^^^^^^^^^^^^^^^^^^^^^^^^^^^^^^^^^^^^^^^^^^^^^^^^^^^^^\n  File \"/home/akil/Desktop/Upwork/Trading Dhan - Krishnan/niftystudy/venv/lib/python3.12/site-packages/urllib3/util/ssl_.py\", line 513, in _ssl_wrap_socket_impl\n    return ssl_context.wrap_socket(sock, server_hostname=server_hostname)\n           ^^^^^^^^^^^^^^^^^^^^^^^^^^^^^^^^^^^^^^^^^^^^^^^^^^^^^^^^^^^^^^\n  File \"/usr/lib/python3.12/ssl.py\", line 455, in wrap_socket\n    return self.sslsocket_class._create(\n           ^^^^^^^^^^^^^^^^^^^^^^^^^^^^^\n  File \"/usr/lib/python3.12/ssl.py\", line 1042, in _create\n    self.do_handshake()\n  File \"/usr/lib/python3.12/ssl.py\", line 1320, in do_handshake\n    self._sslobj.do_handshake()\nurllib3.exceptions.ProtocolError: ('Connection aborted.', ConnectionResetError(104, 'Connection reset by peer'))\n\nDuring handling of the above exception, another exception occurred:\n\nTraceback (most recent call last):\n  File \"/home/akil/Desktop/Upwork/Trading Dhan - Krishnan/niftystudy/venv/lib/python3.12/site-packages/fyers_apiv3/FyersWebsocket/data_ws.py\", line 63, in symbol_to_hsmtoken\n    response = requests.post(\n               ^^^^^^^^^^^^^^\n  File \"/home/akil/Desktop/Upwork/Trading Dhan - Krishnan/niftystudy/venv/lib/python3.12/site-packages/requests/api.py\", line 115, in post\n    return request(\"post\", url, data=data, json=json, **kwargs)\n           ^^^^^^^^^^^^^^^^^^^^^^^^^^^^^^^^^^^^^^^^^^^^^^^^^^^^\n  File \"/home/akil/Desktop/Upwork/Trading Dhan - Krishnan/niftystudy/venv/lib/python3.12/site-packages/requests/api.py\", line 59, in request\n    return session.request(method=method, url=url, **kwargs)\n           ^^^^^^^^^^^^^^^^^^^^^^^^^^^^^^^^^^^^^^^^^^^^^^^^^\n  File \"/home/akil/Desktop/Upwork/Trading Dhan - Krishnan/niftystudy/venv/lib/python3.12/site-packages/requests/sessions.py\", line 589, in request\n    resp = self.send(prep, **send_kwargs)\n           ^^^^^^^^^^^^^^^^^^^^^^^^^^^^^^\n  File \"/home/akil/Desktop/Upwork/Trading Dhan - Krishnan/niftystudy/venv/lib/python3.12/site-packages/requests/sessions.py\", line 703, in send\n    r = adapter.send(request, **kwargs)\n        ^^^^^^^^^^^^^^^^^^^^^^^^^^^^^^^\n  File \"/home/akil/Desktop/Upwork/Trading Dhan - Krishnan/niftystudy/venv/lib/python3.12/site-packages/requests/adapters.py\", line 501, in send\n    raise ConnectionError(err, request=request)\nrequests.exceptions.ConnectionError: ('Connection aborted.', ConnectionResetError(104, 'Connection reset by peer'))","exception_name":"ConnectionError"}
{"level":"ERROR","location":"[__symbol_conversion:1374] data_ws","message":"'NoneType' object is not subscriptable","timestamp":"2024-10-25 06:16:14,780+0000","service":"FyersDataSocket","exception":"Traceback (most recent call last):\n  File \"/home/akil/Desktop/Upwork/Trading Dhan - Krishnan/niftystudy/venv/lib/python3.12/site-packages/websocket/_app.py\", line 428, in setSock\n    dispatcher.read(self.sock.sock, read, check)\n  File \"/home/akil/Desktop/Upwork/Trading Dhan - Krishnan/niftystudy/venv/lib/python3.12/site-packages/websocket/_app.py\", line 99, in read\n    if not read_callback():\n           ^^^^^^^^^^^^^^^\n  File \"/home/akil/Desktop/Upwork/Trading Dhan - Krishnan/niftystudy/venv/lib/python3.12/site-packages/websocket/_app.py\", line 442, in read\n    raise e\n  File \"/home/akil/Desktop/Upwork/Trading Dhan - Krishnan/niftystudy/venv/lib/python3.12/site-packages/websocket/_app.py\", line 437, in read\n    op_code, frame = self.sock.recv_data_frame(True)\n                     ^^^^^^^^^^^^^^^^^^^^^^^^^^^^^^^\n  File \"/home/akil/Desktop/Upwork/Trading Dhan - Krishnan/niftystudy/venv/lib/python3.12/site-packages/websocket/_core.py\", line 406, in recv_data_frame\n    frame = self.recv_frame()\n            ^^^^^^^^^^^^^^^^^\n  File \"/home/akil/Desktop/Upwork/Trading Dhan - Krishnan/niftystudy/venv/lib/python3.12/site-packages/websocket/_core.py\", line 445, in recv_frame\n    return self.frame_buffer.recv_frame()\n           ^^^^^^^^^^^^^^^^^^^^^^^^^^^^^^\n  File \"/home/akil/Desktop/Upwork/Trading Dhan - Krishnan/niftystudy/venv/lib/python3.12/site-packages/websocket/_abnf.py\", line 338, in recv_frame\n    self.recv_header()\n  File \"/home/akil/Desktop/Upwork/Trading Dhan - Krishnan/niftystudy/venv/lib/python3.12/site-packages/websocket/_abnf.py\", line 294, in recv_header\n    header = self.recv_strict(2)\n             ^^^^^^^^^^^^^^^^^^^\n  File \"/home/akil/Desktop/Upwork/Trading Dhan - Krishnan/niftystudy/venv/lib/python3.12/site-packages/websocket/_abnf.py\", line 373, in recv_strict\n    bytes_ = self.recv(min(16384, shortage))\n             ^^^^^^^^^^^^^^^^^^^^^^^^^^^^^^^\n  File \"/home/akil/Desktop/Upwork/Trading Dhan - Krishnan/niftystudy/venv/lib/python3.12/site-packages/websocket/_core.py\", line 529, in _recv\n    return recv(self.sock, bufsize)\n           ^^^^^^^^^^^^^^^^^^^^^^^^\n  File \"/home/akil/Desktop/Upwork/Trading Dhan - Krishnan/niftystudy/venv/lib/python3.12/site-packages/websocket/_socket.py\", line 122, in recv\n    raise WebSocketConnectionClosedException(\nwebsocket._exceptions.WebSocketConnectionClosedException: Connection to remote host was lost.\n\nDuring handling of the above exception, another exception occurred:\n\nTraceback (most recent call last):\n  File \"/home/akil/Desktop/Upwork/Trading Dhan - Krishnan/niftystudy/venv/lib/python3.12/site-packages/fyers_apiv3/FyersWebsocket/data_ws.py\", line 1333, in __symbol_conversion\n    if symbol_value[3] != \"\":\n       ~~~~~~~~~~~~^^^\nTypeError: 'NoneType' object is not subscriptable","exception_name":"TypeError"}
